2020-05-24 17:08:43,381 p=18427 u=root n=ansible | ERROR! The vault password file /root/automate/docker/praveen.pem was not found
2020-05-24 17:10:48,880 p=18531 u=root n=ansible | PLAY [dev] ******************************************************************************************************************************************
2020-05-24 17:10:48,904 p=18531 u=root n=ansible | TASK [Gathering Facts] ******************************************************************************************************************************
2020-05-24 17:10:52,287 p=18531 u=root n=ansible | ok: [node03]
2020-05-24 17:10:52,463 p=18531 u=root n=ansible | ok: [node01]
2020-05-24 17:10:52,475 p=18531 u=root n=ansible | ok: [node02]
2020-05-24 17:10:52,515 p=18531 u=root n=ansible | TASK [loading file] *********************************************************************************************************************************
2020-05-24 17:10:53,757 p=18531 u=root n=ansible | changed: [node02]
2020-05-24 17:10:53,889 p=18531 u=root n=ansible | changed: [node01]
2020-05-24 17:10:53,905 p=18531 u=root n=ansible | changed: [node03]
2020-05-24 17:10:53,938 p=18531 u=root n=ansible | TASK [Adding files] *********************************************************************************************************************************
2020-05-24 17:10:55,372 p=18531 u=root n=ansible | An exception occurred during task execution. To see the full traceback, use -vvv. The error was: NameError: name 'op' is not defined
2020-05-24 17:10:55,373 p=18531 u=root n=ansible | fatal: [node02]: FAILED! => {"changed": false, "module_stderr": "Shared connection to 192.168.56.2 closed.\r\n", "module_stdout": "Traceback (most recent call last):\r\n  File \"/home/vagrant/.ansible/tmp/ansible-tmp-1590329454.1871796-78445139936364/AnsiballZ_wordmatch.py\", line 102, in <module>\r\n    _ansiballz_main()\r\n  File \"/home/vagrant/.ansible/tmp/ansible-tmp-1590329454.1871796-78445139936364/AnsiballZ_wordmatch.py\", line 94, in _ansiballz_main\r\n    invoke_module(zipped_mod, temp_path, ANSIBALLZ_PARAMS)\r\n  File \"/home/vagrant/.ansible/tmp/ansible-tmp-1590329454.1871796-78445139936364/AnsiballZ_wordmatch.py\", line 40, in invoke_module\r\n    runpy.run_module(mod_name='ansible.modules.wordmatch', init_globals=None, run_name='__main__', alter_sys=True)\r\n  File \"/usr/lib64/python2.7/runpy.py\", line 176, in run_module\r\n    fname, loader, pkg_name)\r\n  File \"/usr/lib64/python2.7/runpy.py\", line 82, in _run_module_code\r\n    mod_name, mod_fname, mod_loader, pkg_name)\r\n  File \"/usr/lib64/python2.7/runpy.py\", line 72, in _run_code\r\n    exec code in run_globals\r\n  File \"/tmp/ansible_wordmatch_payload_OoyRLl/ansible_wordmatch_payload.zip/ansible/modules/wordmatch.py\", line 20, in <module>\r\nNameError: name 'op' is not defined\r\n", "msg": "MODULE FAILURE\nSee stdout/stderr for the exact error", "rc": 1}
2020-05-24 17:10:55,440 p=18531 u=root n=ansible | An exception occurred during task execution. To see the full traceback, use -vvv. The error was: NameError: name 'op' is not defined
2020-05-24 17:10:55,440 p=18531 u=root n=ansible | fatal: [node03]: FAILED! => {"changed": false, "module_stderr": "Shared connection to 192.168.56.2 closed.\r\n", "module_stdout": "Traceback (most recent call last):\r\n  File \"/home/vagrant/.ansible/tmp/ansible-tmp-1590329454.2727835-16460885600844/AnsiballZ_wordmatch.py\", line 102, in <module>\r\n    _ansiballz_main()\r\n  File \"/home/vagrant/.ansible/tmp/ansible-tmp-1590329454.2727835-16460885600844/AnsiballZ_wordmatch.py\", line 94, in _ansiballz_main\r\n    invoke_module(zipped_mod, temp_path, ANSIBALLZ_PARAMS)\r\n  File \"/home/vagrant/.ansible/tmp/ansible-tmp-1590329454.2727835-16460885600844/AnsiballZ_wordmatch.py\", line 40, in invoke_module\r\n    runpy.run_module(mod_name='ansible.modules.wordmatch', init_globals=None, run_name='__main__', alter_sys=True)\r\n  File \"/usr/lib64/python2.7/runpy.py\", line 176, in run_module\r\n    fname, loader, pkg_name)\r\n  File \"/usr/lib64/python2.7/runpy.py\", line 82, in _run_module_code\r\n    mod_name, mod_fname, mod_loader, pkg_name)\r\n  File \"/usr/lib64/python2.7/runpy.py\", line 72, in _run_code\r\n    exec code in run_globals\r\n  File \"/tmp/ansible_wordmatch_payload_ulyNzE/ansible_wordmatch_payload.zip/ansible/modules/wordmatch.py\", line 20, in <module>\r\nNameError: name 'op' is not defined\r\n", "msg": "MODULE FAILURE\nSee stdout/stderr for the exact error", "rc": 1}
2020-05-24 17:10:55,478 p=18531 u=root n=ansible | An exception occurred during task execution. To see the full traceback, use -vvv. The error was: NameError: name 'op' is not defined
2020-05-24 17:10:55,479 p=18531 u=root n=ansible | fatal: [node01]: FAILED! => {"changed": false, "module_stderr": "Shared connection to 192.168.56.2 closed.\r\n", "module_stdout": "Traceback (most recent call last):\r\n  File \"/home/vagrant/.ansible/tmp/ansible-tmp-1590329454.096169-28790236213537/AnsiballZ_wordmatch.py\", line 102, in <module>\r\n    _ansiballz_main()\r\n  File \"/home/vagrant/.ansible/tmp/ansible-tmp-1590329454.096169-28790236213537/AnsiballZ_wordmatch.py\", line 94, in _ansiballz_main\r\n    invoke_module(zipped_mod, temp_path, ANSIBALLZ_PARAMS)\r\n  File \"/home/vagrant/.ansible/tmp/ansible-tmp-1590329454.096169-28790236213537/AnsiballZ_wordmatch.py\", line 40, in invoke_module\r\n    runpy.run_module(mod_name='ansible.modules.wordmatch', init_globals=None, run_name='__main__', alter_sys=True)\r\n  File \"/usr/lib64/python2.7/runpy.py\", line 176, in run_module\r\n    fname, loader, pkg_name)\r\n  File \"/usr/lib64/python2.7/runpy.py\", line 82, in _run_module_code\r\n    mod_name, mod_fname, mod_loader, pkg_name)\r\n  File \"/usr/lib64/python2.7/runpy.py\", line 72, in _run_code\r\n    exec code in run_globals\r\n  File \"/tmp/ansible_wordmatch_payload_DGMwLU/ansible_wordmatch_payload.zip/ansible/modules/wordmatch.py\", line 20, in <module>\r\nNameError: name 'op' is not defined\r\n", "msg": "MODULE FAILURE\nSee stdout/stderr for the exact error", "rc": 1}
2020-05-24 17:10:55,483 p=18531 u=root n=ansible | PLAY RECAP ******************************************************************************************************************************************
2020-05-24 17:10:55,483 p=18531 u=root n=ansible | node01                     : ok=2    changed=1    unreachable=0    failed=1    skipped=0    rescued=0    ignored=0   
2020-05-24 17:10:55,484 p=18531 u=root n=ansible | node02                     : ok=2    changed=1    unreachable=0    failed=1    skipped=0    rescued=0    ignored=0   
2020-05-24 17:10:55,484 p=18531 u=root n=ansible | node03                     : ok=2    changed=1    unreachable=0    failed=1    skipped=0    rescued=0    ignored=0   
2020-05-24 17:22:46,758 p=19452 u=root n=ansible | PLAY [dev] ******************************************************************************************************************************************
2020-05-24 17:22:46,781 p=19452 u=root n=ansible | TASK [Gathering Facts] ******************************************************************************************************************************
2020-05-24 17:22:50,438 p=19452 u=root n=ansible | ok: [node03]
2020-05-24 17:22:50,620 p=19452 u=root n=ansible | ok: [node02]
2020-05-24 17:22:50,634 p=19452 u=root n=ansible | ok: [node01]
2020-05-24 17:22:50,671 p=19452 u=root n=ansible | TASK [loading file] *********************************************************************************************************************************
2020-05-24 17:22:51,940 p=19452 u=root n=ansible | changed: [node02]
2020-05-24 17:22:52,104 p=19452 u=root n=ansible | changed: [node03]
2020-05-24 17:22:52,111 p=19452 u=root n=ansible | changed: [node01]
2020-05-24 17:22:52,143 p=19452 u=root n=ansible | TASK [Adding files] *********************************************************************************************************************************
2020-05-24 17:22:53,554 p=19452 u=root n=ansible | An exception occurred during task execution. To see the full traceback, use -vvv. The error was: NameError: name 'op' is not defined
2020-05-24 17:22:53,555 p=19452 u=root n=ansible | fatal: [node02]: FAILED! => {"changed": false, "module_stderr": "Shared connection to 192.168.56.2 closed.\r\n", "module_stdout": "Traceback (most recent call last):\r\n  File \"/home/vagrant/.ansible/tmp/ansible-tmp-1590330172.400504-58806363165273/AnsiballZ_wordmatch.py\", line 102, in <module>\r\n    _ansiballz_main()\r\n  File \"/home/vagrant/.ansible/tmp/ansible-tmp-1590330172.400504-58806363165273/AnsiballZ_wordmatch.py\", line 94, in _ansiballz_main\r\n    invoke_module(zipped_mod, temp_path, ANSIBALLZ_PARAMS)\r\n  File \"/home/vagrant/.ansible/tmp/ansible-tmp-1590330172.400504-58806363165273/AnsiballZ_wordmatch.py\", line 40, in invoke_module\r\n    runpy.run_module(mod_name='ansible.modules.wordmatch', init_globals=None, run_name='__main__', alter_sys=True)\r\n  File \"/usr/lib64/python2.7/runpy.py\", line 176, in run_module\r\n    fname, loader, pkg_name)\r\n  File \"/usr/lib64/python2.7/runpy.py\", line 82, in _run_module_code\r\n    mod_name, mod_fname, mod_loader, pkg_name)\r\n  File \"/usr/lib64/python2.7/runpy.py\", line 72, in _run_code\r\n    exec code in run_globals\r\n  File \"/tmp/ansible_wordmatch_payload_aEWTDx/ansible_wordmatch_payload.zip/ansible/modules/wordmatch.py\", line 17, in <module>\r\nNameError: name 'op' is not defined\r\n", "msg": "MODULE FAILURE\nSee stdout/stderr for the exact error", "rc": 1}
2020-05-24 17:22:53,678 p=19452 u=root n=ansible | An exception occurred during task execution. To see the full traceback, use -vvv. The error was: NameError: name 'op' is not defined
2020-05-24 17:22:53,679 p=19452 u=root n=ansible | fatal: [node03]: FAILED! => {"changed": false, "module_stderr": "Shared connection to 192.168.56.2 closed.\r\n", "module_stdout": "Traceback (most recent call last):\r\n  File \"/home/vagrant/.ansible/tmp/ansible-tmp-1590330172.4662354-145932312678032/AnsiballZ_wordmatch.py\", line 102, in <module>\r\n    _ansiballz_main()\r\n  File \"/home/vagrant/.ansible/tmp/ansible-tmp-1590330172.4662354-145932312678032/AnsiballZ_wordmatch.py\", line 94, in _ansiballz_main\r\n    invoke_module(zipped_mod, temp_path, ANSIBALLZ_PARAMS)\r\n  File \"/home/vagrant/.ansible/tmp/ansible-tmp-1590330172.4662354-145932312678032/AnsiballZ_wordmatch.py\", line 40, in invoke_module\r\n    runpy.run_module(mod_name='ansible.modules.wordmatch', init_globals=None, run_name='__main__', alter_sys=True)\r\n  File \"/usr/lib64/python2.7/runpy.py\", line 176, in run_module\r\n    fname, loader, pkg_name)\r\n  File \"/usr/lib64/python2.7/runpy.py\", line 82, in _run_module_code\r\n    mod_name, mod_fname, mod_loader, pkg_name)\r\n  File \"/usr/lib64/python2.7/runpy.py\", line 72, in _run_code\r\n    exec code in run_globals\r\n  File \"/tmp/ansible_wordmatch_payload_y2dbFi/ansible_wordmatch_payload.zip/ansible/modules/wordmatch.py\", line 17, in <module>\r\nNameError: name 'op' is not defined\r\n", "msg": "MODULE FAILURE\nSee stdout/stderr for the exact error", "rc": 1}
2020-05-24 17:22:53,692 p=19452 u=root n=ansible | An exception occurred during task execution. To see the full traceback, use -vvv. The error was: NameError: name 'op' is not defined
2020-05-24 17:22:53,692 p=19452 u=root n=ansible | fatal: [node01]: FAILED! => {"changed": false, "module_stderr": "Shared connection to 192.168.56.2 closed.\r\n", "module_stdout": "Traceback (most recent call last):\r\n  File \"/home/vagrant/.ansible/tmp/ansible-tmp-1590330172.3049011-157722396153804/AnsiballZ_wordmatch.py\", line 102, in <module>\r\n    _ansiballz_main()\r\n  File \"/home/vagrant/.ansible/tmp/ansible-tmp-1590330172.3049011-157722396153804/AnsiballZ_wordmatch.py\", line 94, in _ansiballz_main\r\n    invoke_module(zipped_mod, temp_path, ANSIBALLZ_PARAMS)\r\n  File \"/home/vagrant/.ansible/tmp/ansible-tmp-1590330172.3049011-157722396153804/AnsiballZ_wordmatch.py\", line 40, in invoke_module\r\n    runpy.run_module(mod_name='ansible.modules.wordmatch', init_globals=None, run_name='__main__', alter_sys=True)\r\n  File \"/usr/lib64/python2.7/runpy.py\", line 176, in run_module\r\n    fname, loader, pkg_name)\r\n  File \"/usr/lib64/python2.7/runpy.py\", line 82, in _run_module_code\r\n    mod_name, mod_fname, mod_loader, pkg_name)\r\n  File \"/usr/lib64/python2.7/runpy.py\", line 72, in _run_code\r\n    exec code in run_globals\r\n  File \"/tmp/ansible_wordmatch_payload_rxYd26/ansible_wordmatch_payload.zip/ansible/modules/wordmatch.py\", line 17, in <module>\r\nNameError: name 'op' is not defined\r\n", "msg": "MODULE FAILURE\nSee stdout/stderr for the exact error", "rc": 1}
2020-05-24 17:22:53,693 p=19452 u=root n=ansible | PLAY RECAP ******************************************************************************************************************************************
2020-05-24 17:22:53,694 p=19452 u=root n=ansible | node01                     : ok=2    changed=1    unreachable=0    failed=1    skipped=0    rescued=0    ignored=0   
2020-05-24 17:22:53,694 p=19452 u=root n=ansible | node02                     : ok=2    changed=1    unreachable=0    failed=1    skipped=0    rescued=0    ignored=0   
2020-05-24 17:22:53,694 p=19452 u=root n=ansible | node03                     : ok=2    changed=1    unreachable=0    failed=1    skipped=0    rescued=0    ignored=0   
2020-05-24 17:24:45,337 p=19810 u=root n=ansible |  [ERROR]: User interrupted execution

2020-05-24 17:24:52,922 p=19818 u=root n=ansible | PLAY [dev] ******************************************************************************************************************************************
2020-05-24 17:24:52,942 p=19818 u=root n=ansible | TASK [Gathering Facts] ******************************************************************************************************************************
2020-05-24 17:24:56,085 p=19818 u=root n=ansible | ok: [node02]
2020-05-24 17:24:56,262 p=19818 u=root n=ansible | ok: [node01]
2020-05-24 17:24:56,319 p=19818 u=root n=ansible | ok: [node03]
2020-05-24 17:24:56,352 p=19818 u=root n=ansible | TASK [loading file] *********************************************************************************************************************************
2020-05-24 17:24:57,605 p=19818 u=root n=ansible | changed: [node02]
2020-05-24 17:24:57,768 p=19818 u=root n=ansible | changed: [node01]
2020-05-24 17:24:57,775 p=19818 u=root n=ansible | changed: [node03]
2020-05-24 17:24:57,810 p=19818 u=root n=ansible | TASK [Adding files] *********************************************************************************************************************************
2020-05-24 17:24:59,143 p=19818 u=root n=ansible | An exception occurred during task execution. To see the full traceback, use -vvv. The error was: NameError: name 'op' is not defined
2020-05-24 17:24:59,144 p=19818 u=root n=ansible | fatal: [node02]: FAILED! => {"changed": false, "module_stderr": "Shared connection to 192.168.56.2 closed.\r\n", "module_stdout": "Traceback (most recent call last):\r\n  File \"/home/vagrant/.ansible/tmp/ansible-tmp-1590330298.0626647-197456965824168/AnsiballZ_wordmatch.py\", line 102, in <module>\r\n    _ansiballz_main()\r\n  File \"/home/vagrant/.ansible/tmp/ansible-tmp-1590330298.0626647-197456965824168/AnsiballZ_wordmatch.py\", line 94, in _ansiballz_main\r\n    invoke_module(zipped_mod, temp_path, ANSIBALLZ_PARAMS)\r\n  File \"/home/vagrant/.ansible/tmp/ansible-tmp-1590330298.0626647-197456965824168/AnsiballZ_wordmatch.py\", line 40, in invoke_module\r\n    runpy.run_module(mod_name='ansible.modules.wordmatch', init_globals=None, run_name='__main__', alter_sys=True)\r\n  File \"/usr/lib64/python2.7/runpy.py\", line 176, in run_module\r\n    fname, loader, pkg_name)\r\n  File \"/usr/lib64/python2.7/runpy.py\", line 82, in _run_module_code\r\n    mod_name, mod_fname, mod_loader, pkg_name)\r\n  File \"/usr/lib64/python2.7/runpy.py\", line 72, in _run_code\r\n    exec code in run_globals\r\n  File \"/tmp/ansible_wordmatch_payload_FRoyLD/ansible_wordmatch_payload.zip/ansible/modules/wordmatch.py\", line 20, in <module>\r\nNameError: name 'op' is not defined\r\n", "msg": "MODULE FAILURE\nSee stdout/stderr for the exact error", "rc": 1}
2020-05-24 17:24:59,286 p=19818 u=root n=ansible | An exception occurred during task execution. To see the full traceback, use -vvv. The error was: NameError: name 'op' is not defined
2020-05-24 17:24:59,286 p=19818 u=root n=ansible | fatal: [node03]: FAILED! => {"changed": false, "module_stderr": "Shared connection to 192.168.56.2 closed.\r\n", "module_stdout": "Traceback (most recent call last):\r\n  File \"/home/vagrant/.ansible/tmp/ansible-tmp-1590330298.1571593-135235726809668/AnsiballZ_wordmatch.py\", line 102, in <module>\r\n    _ansiballz_main()\r\n  File \"/home/vagrant/.ansible/tmp/ansible-tmp-1590330298.1571593-135235726809668/AnsiballZ_wordmatch.py\", line 94, in _ansiballz_main\r\n    invoke_module(zipped_mod, temp_path, ANSIBALLZ_PARAMS)\r\n  File \"/home/vagrant/.ansible/tmp/ansible-tmp-1590330298.1571593-135235726809668/AnsiballZ_wordmatch.py\", line 40, in invoke_module\r\n    runpy.run_module(mod_name='ansible.modules.wordmatch', init_globals=None, run_name='__main__', alter_sys=True)\r\n  File \"/usr/lib64/python2.7/runpy.py\", line 176, in run_module\r\n    fname, loader, pkg_name)\r\n  File \"/usr/lib64/python2.7/runpy.py\", line 82, in _run_module_code\r\n    mod_name, mod_fname, mod_loader, pkg_name)\r\n  File \"/usr/lib64/python2.7/runpy.py\", line 72, in _run_code\r\n    exec code in run_globals\r\n  File \"/tmp/ansible_wordmatch_payload_gI9w6y/ansible_wordmatch_payload.zip/ansible/modules/wordmatch.py\", line 20, in <module>\r\nNameError: name 'op' is not defined\r\n", "msg": "MODULE FAILURE\nSee stdout/stderr for the exact error", "rc": 1}
2020-05-24 17:24:59,307 p=19818 u=root n=ansible | An exception occurred during task execution. To see the full traceback, use -vvv. The error was: NameError: name 'op' is not defined
2020-05-24 17:24:59,308 p=19818 u=root n=ansible | fatal: [node01]: FAILED! => {"changed": false, "module_stderr": "Shared connection to 192.168.56.2 closed.\r\n", "module_stdout": "Traceback (most recent call last):\r\n  File \"/home/vagrant/.ansible/tmp/ansible-tmp-1590330297.9736984-280146243255067/AnsiballZ_wordmatch.py\", line 102, in <module>\r\n    _ansiballz_main()\r\n  File \"/home/vagrant/.ansible/tmp/ansible-tmp-1590330297.9736984-280146243255067/AnsiballZ_wordmatch.py\", line 94, in _ansiballz_main\r\n    invoke_module(zipped_mod, temp_path, ANSIBALLZ_PARAMS)\r\n  File \"/home/vagrant/.ansible/tmp/ansible-tmp-1590330297.9736984-280146243255067/AnsiballZ_wordmatch.py\", line 40, in invoke_module\r\n    runpy.run_module(mod_name='ansible.modules.wordmatch', init_globals=None, run_name='__main__', alter_sys=True)\r\n  File \"/usr/lib64/python2.7/runpy.py\", line 176, in run_module\r\n    fname, loader, pkg_name)\r\n  File \"/usr/lib64/python2.7/runpy.py\", line 82, in _run_module_code\r\n    mod_name, mod_fname, mod_loader, pkg_name)\r\n  File \"/usr/lib64/python2.7/runpy.py\", line 72, in _run_code\r\n    exec code in run_globals\r\n  File \"/tmp/ansible_wordmatch_payload_sX_htu/ansible_wordmatch_payload.zip/ansible/modules/wordmatch.py\", line 20, in <module>\r\nNameError: name 'op' is not defined\r\n", "msg": "MODULE FAILURE\nSee stdout/stderr for the exact error", "rc": 1}
2020-05-24 17:24:59,309 p=19818 u=root n=ansible | PLAY RECAP ******************************************************************************************************************************************
2020-05-24 17:24:59,310 p=19818 u=root n=ansible | node01                     : ok=2    changed=1    unreachable=0    failed=1    skipped=0    rescued=0    ignored=0   
2020-05-24 17:24:59,310 p=19818 u=root n=ansible | node02                     : ok=2    changed=1    unreachable=0    failed=1    skipped=0    rescued=0    ignored=0   
2020-05-24 17:24:59,310 p=19818 u=root n=ansible | node03                     : ok=2    changed=1    unreachable=0    failed=1    skipped=0    rescued=0    ignored=0   
2020-05-24 17:28:08,542 p=20313 u=root n=ansible | PLAY [dev] ******************************************************************************************************************************************
2020-05-24 17:28:08,562 p=20313 u=root n=ansible | TASK [Gathering Facts] ******************************************************************************************************************************
2020-05-24 17:28:11,780 p=20313 u=root n=ansible | ok: [node03]
2020-05-24 17:28:11,933 p=20313 u=root n=ansible | ok: [node01]
2020-05-24 17:28:11,945 p=20313 u=root n=ansible | ok: [node02]
2020-05-24 17:28:11,984 p=20313 u=root n=ansible | TASK [loading file] *********************************************************************************************************************************
2020-05-24 17:28:13,250 p=20313 u=root n=ansible | changed: [node02]
2020-05-24 17:28:13,421 p=20313 u=root n=ansible | changed: [node03]
2020-05-24 17:28:13,428 p=20313 u=root n=ansible | changed: [node01]
2020-05-24 17:28:13,461 p=20313 u=root n=ansible | TASK [Adding files] *********************************************************************************************************************************
2020-05-24 17:28:14,671 p=20313 u=root n=ansible | An exception occurred during task execution. To see the full traceback, use -vvv. The error was: NameError: name 'op' is not defined
2020-05-24 17:28:14,671 p=20313 u=root n=ansible | fatal: [node02]: FAILED! => {"changed": false, "module_stderr": "Shared connection to 192.168.56.2 closed.\r\n", "module_stdout": "Traceback (most recent call last):\r\n  File \"/home/vagrant/.ansible/tmp/ansible-tmp-1590330493.566511-231462086028918/AnsiballZ_wordmatch.py\", line 102, in <module>\r\n    _ansiballz_main()\r\n  File \"/home/vagrant/.ansible/tmp/ansible-tmp-1590330493.566511-231462086028918/AnsiballZ_wordmatch.py\", line 94, in _ansiballz_main\r\n    invoke_module(zipped_mod, temp_path, ANSIBALLZ_PARAMS)\r\n  File \"/home/vagrant/.ansible/tmp/ansible-tmp-1590330493.566511-231462086028918/AnsiballZ_wordmatch.py\", line 40, in invoke_module\r\n    runpy.run_module(mod_name='ansible.modules.wordmatch', init_globals=None, run_name='__main__', alter_sys=True)\r\n  File \"/usr/lib64/python2.7/runpy.py\", line 176, in run_module\r\n    fname, loader, pkg_name)\r\n  File \"/usr/lib64/python2.7/runpy.py\", line 82, in _run_module_code\r\n    mod_name, mod_fname, mod_loader, pkg_name)\r\n  File \"/usr/lib64/python2.7/runpy.py\", line 72, in _run_code\r\n    exec code in run_globals\r\n  File \"/tmp/ansible_wordmatch_payload_4zjufu/ansible_wordmatch_payload.zip/ansible/modules/wordmatch.py\", line 20, in <module>\r\nNameError: name 'op' is not defined\r\n", "msg": "MODULE FAILURE\nSee stdout/stderr for the exact error", "rc": 1}
2020-05-24 17:28:14,804 p=20313 u=root n=ansible | An exception occurred during task execution. To see the full traceback, use -vvv. The error was: NameError: name 'op' is not defined
2020-05-24 17:28:14,805 p=20313 u=root n=ansible | fatal: [node03]: FAILED! => {"changed": false, "module_stderr": "Shared connection to 192.168.56.2 closed.\r\n", "module_stdout": "Traceback (most recent call last):\r\n  File \"/home/vagrant/.ansible/tmp/ansible-tmp-1590330493.6219938-175237764496440/AnsiballZ_wordmatch.py\", line 102, in <module>\r\n    _ansiballz_main()\r\n  File \"/home/vagrant/.ansible/tmp/ansible-tmp-1590330493.6219938-175237764496440/AnsiballZ_wordmatch.py\", line 94, in _ansiballz_main\r\n    invoke_module(zipped_mod, temp_path, ANSIBALLZ_PARAMS)\r\n  File \"/home/vagrant/.ansible/tmp/ansible-tmp-1590330493.6219938-175237764496440/AnsiballZ_wordmatch.py\", line 40, in invoke_module\r\n    runpy.run_module(mod_name='ansible.modules.wordmatch', init_globals=None, run_name='__main__', alter_sys=True)\r\n  File \"/usr/lib64/python2.7/runpy.py\", line 176, in run_module\r\n    fname, loader, pkg_name)\r\n  File \"/usr/lib64/python2.7/runpy.py\", line 82, in _run_module_code\r\n    mod_name, mod_fname, mod_loader, pkg_name)\r\n  File \"/usr/lib64/python2.7/runpy.py\", line 72, in _run_code\r\n    exec code in run_globals\r\n  File \"/tmp/ansible_wordmatch_payload_WK97v5/ansible_wordmatch_payload.zip/ansible/modules/wordmatch.py\", line 20, in <module>\r\nNameError: name 'op' is not defined\r\n", "msg": "MODULE FAILURE\nSee stdout/stderr for the exact error", "rc": 1}
2020-05-24 17:28:14,821 p=20313 u=root n=ansible | An exception occurred during task execution. To see the full traceback, use -vvv. The error was: NameError: name 'op' is not defined
2020-05-24 17:28:14,821 p=20313 u=root n=ansible | fatal: [node01]: FAILED! => {"changed": false, "module_stderr": "Shared connection to 192.168.56.2 closed.\r\n", "module_stdout": "Traceback (most recent call last):\r\n  File \"/home/vagrant/.ansible/tmp/ansible-tmp-1590330493.4933136-155510729312143/AnsiballZ_wordmatch.py\", line 102, in <module>\r\n    _ansiballz_main()\r\n  File \"/home/vagrant/.ansible/tmp/ansible-tmp-1590330493.4933136-155510729312143/AnsiballZ_wordmatch.py\", line 94, in _ansiballz_main\r\n    invoke_module(zipped_mod, temp_path, ANSIBALLZ_PARAMS)\r\n  File \"/home/vagrant/.ansible/tmp/ansible-tmp-1590330493.4933136-155510729312143/AnsiballZ_wordmatch.py\", line 40, in invoke_module\r\n    runpy.run_module(mod_name='ansible.modules.wordmatch', init_globals=None, run_name='__main__', alter_sys=True)\r\n  File \"/usr/lib64/python2.7/runpy.py\", line 176, in run_module\r\n    fname, loader, pkg_name)\r\n  File \"/usr/lib64/python2.7/runpy.py\", line 82, in _run_module_code\r\n    mod_name, mod_fname, mod_loader, pkg_name)\r\n  File \"/usr/lib64/python2.7/runpy.py\", line 72, in _run_code\r\n    exec code in run_globals\r\n  File \"/tmp/ansible_wordmatch_payload_hKdC95/ansible_wordmatch_payload.zip/ansible/modules/wordmatch.py\", line 20, in <module>\r\nNameError: name 'op' is not defined\r\n", "msg": "MODULE FAILURE\nSee stdout/stderr for the exact error", "rc": 1}
2020-05-24 17:28:14,823 p=20313 u=root n=ansible | PLAY RECAP ******************************************************************************************************************************************
2020-05-24 17:28:14,823 p=20313 u=root n=ansible | node01                     : ok=2    changed=1    unreachable=0    failed=1    skipped=0    rescued=0    ignored=0   
2020-05-24 17:28:14,823 p=20313 u=root n=ansible | node02                     : ok=2    changed=1    unreachable=0    failed=1    skipped=0    rescued=0    ignored=0   
2020-05-24 17:28:14,823 p=20313 u=root n=ansible | node03                     : ok=2    changed=1    unreachable=0    failed=1    skipped=0    rescued=0    ignored=0   
2020-05-24 17:29:24,007 p=20540 u=root n=ansible | PLAY [dev] ******************************************************************************************************************************************
2020-05-24 17:29:24,027 p=20540 u=root n=ansible | TASK [Gathering Facts] ******************************************************************************************************************************
2020-05-24 17:29:27,250 p=20540 u=root n=ansible | ok: [node01]
2020-05-24 17:29:27,441 p=20540 u=root n=ansible | ok: [node03]
2020-05-24 17:29:27,450 p=20540 u=root n=ansible | ok: [node02]
2020-05-24 17:29:27,487 p=20540 u=root n=ansible | TASK [loading file] *********************************************************************************************************************************
2020-05-24 17:29:28,792 p=20540 u=root n=ansible | changed: [node01]
2020-05-24 17:29:28,940 p=20540 u=root n=ansible | changed: [node02]
2020-05-24 17:29:28,947 p=20540 u=root n=ansible | changed: [node03]
2020-05-24 17:29:28,981 p=20540 u=root n=ansible | TASK [Adding files] *********************************************************************************************************************************
2020-05-24 17:29:30,233 p=20540 u=root n=ansible | An exception occurred during task execution. To see the full traceback, use -vvv. The error was: NameError: name 'op' is not defined
2020-05-24 17:29:30,234 p=20540 u=root n=ansible | fatal: [node03]: FAILED! => {"changed": false, "module_stderr": "Shared connection to 192.168.56.2 closed.\r\n", "module_stdout": "Traceback (most recent call last):\r\n  File \"/home/vagrant/.ansible/tmp/ansible-tmp-1590330569.1466572-137150943617396/AnsiballZ_wordmatch.py\", line 102, in <module>\r\n    _ansiballz_main()\r\n  File \"/home/vagrant/.ansible/tmp/ansible-tmp-1590330569.1466572-137150943617396/AnsiballZ_wordmatch.py\", line 94, in _ansiballz_main\r\n    invoke_module(zipped_mod, temp_path, ANSIBALLZ_PARAMS)\r\n  File \"/home/vagrant/.ansible/tmp/ansible-tmp-1590330569.1466572-137150943617396/AnsiballZ_wordmatch.py\", line 40, in invoke_module\r\n    runpy.run_module(mod_name='ansible.modules.wordmatch', init_globals=None, run_name='__main__', alter_sys=True)\r\n  File \"/usr/lib64/python2.7/runpy.py\", line 176, in run_module\r\n    fname, loader, pkg_name)\r\n  File \"/usr/lib64/python2.7/runpy.py\", line 82, in _run_module_code\r\n    mod_name, mod_fname, mod_loader, pkg_name)\r\n  File \"/usr/lib64/python2.7/runpy.py\", line 72, in _run_code\r\n    exec code in run_globals\r\n  File \"/tmp/ansible_wordmatch_payload_13aMTO/ansible_wordmatch_payload.zip/ansible/modules/wordmatch.py\", line 20, in <module>\r\nNameError: name 'op' is not defined\r\n", "msg": "MODULE FAILURE\nSee stdout/stderr for the exact error", "rc": 1}
2020-05-24 17:29:30,299 p=20540 u=root n=ansible | An exception occurred during task execution. To see the full traceback, use -vvv. The error was: NameError: name 'op' is not defined
2020-05-24 17:29:30,300 p=20540 u=root n=ansible | fatal: [node01]: FAILED! => {"changed": false, "module_stderr": "Shared connection to 192.168.56.2 closed.\r\n", "module_stdout": "Traceback (most recent call last):\r\n  File \"/home/vagrant/.ansible/tmp/ansible-tmp-1590330569.015605-128975917211624/AnsiballZ_wordmatch.py\", line 102, in <module>\r\n    _ansiballz_main()\r\n  File \"/home/vagrant/.ansible/tmp/ansible-tmp-1590330569.015605-128975917211624/AnsiballZ_wordmatch.py\", line 94, in _ansiballz_main\r\n    invoke_module(zipped_mod, temp_path, ANSIBALLZ_PARAMS)\r\n  File \"/home/vagrant/.ansible/tmp/ansible-tmp-1590330569.015605-128975917211624/AnsiballZ_wordmatch.py\", line 40, in invoke_module\r\n    runpy.run_module(mod_name='ansible.modules.wordmatch', init_globals=None, run_name='__main__', alter_sys=True)\r\n  File \"/usr/lib64/python2.7/runpy.py\", line 176, in run_module\r\n    fname, loader, pkg_name)\r\n  File \"/usr/lib64/python2.7/runpy.py\", line 82, in _run_module_code\r\n    mod_name, mod_fname, mod_loader, pkg_name)\r\n  File \"/usr/lib64/python2.7/runpy.py\", line 72, in _run_code\r\n    exec code in run_globals\r\n  File \"/tmp/ansible_wordmatch_payload_ceeTTS/ansible_wordmatch_payload.zip/ansible/modules/wordmatch.py\", line 20, in <module>\r\nNameError: name 'op' is not defined\r\n", "msg": "MODULE FAILURE\nSee stdout/stderr for the exact error", "rc": 1}
2020-05-24 17:29:30,319 p=20540 u=root n=ansible | An exception occurred during task execution. To see the full traceback, use -vvv. The error was: NameError: name 'op' is not defined
2020-05-24 17:29:30,319 p=20540 u=root n=ansible | fatal: [node02]: FAILED! => {"changed": false, "module_stderr": "Shared connection to 192.168.56.2 closed.\r\n", "module_stdout": "Traceback (most recent call last):\r\n  File \"/home/vagrant/.ansible/tmp/ansible-tmp-1590330569.080898-64023126574339/AnsiballZ_wordmatch.py\", line 102, in <module>\r\n    _ansiballz_main()\r\n  File \"/home/vagrant/.ansible/tmp/ansible-tmp-1590330569.080898-64023126574339/AnsiballZ_wordmatch.py\", line 94, in _ansiballz_main\r\n    invoke_module(zipped_mod, temp_path, ANSIBALLZ_PARAMS)\r\n  File \"/home/vagrant/.ansible/tmp/ansible-tmp-1590330569.080898-64023126574339/AnsiballZ_wordmatch.py\", line 40, in invoke_module\r\n    runpy.run_module(mod_name='ansible.modules.wordmatch', init_globals=None, run_name='__main__', alter_sys=True)\r\n  File \"/usr/lib64/python2.7/runpy.py\", line 176, in run_module\r\n    fname, loader, pkg_name)\r\n  File \"/usr/lib64/python2.7/runpy.py\", line 82, in _run_module_code\r\n    mod_name, mod_fname, mod_loader, pkg_name)\r\n  File \"/usr/lib64/python2.7/runpy.py\", line 72, in _run_code\r\n    exec code in run_globals\r\n  File \"/tmp/ansible_wordmatch_payload_HO9wZ7/ansible_wordmatch_payload.zip/ansible/modules/wordmatch.py\", line 20, in <module>\r\nNameError: name 'op' is not defined\r\n", "msg": "MODULE FAILURE\nSee stdout/stderr for the exact error", "rc": 1}
2020-05-24 17:29:30,321 p=20540 u=root n=ansible | PLAY RECAP ******************************************************************************************************************************************
2020-05-24 17:29:30,321 p=20540 u=root n=ansible | node01                     : ok=2    changed=1    unreachable=0    failed=1    skipped=0    rescued=0    ignored=0   
2020-05-24 17:29:30,321 p=20540 u=root n=ansible | node02                     : ok=2    changed=1    unreachable=0    failed=1    skipped=0    rescued=0    ignored=0   
2020-05-24 17:29:30,321 p=20540 u=root n=ansible | node03                     : ok=2    changed=1    unreachable=0    failed=1    skipped=0    rescued=0    ignored=0   
2020-05-24 17:39:59,560 p=21217 u=root n=ansible | PLAY [dev] ******************************************************************************************************************************************
2020-05-24 17:39:59,581 p=21217 u=root n=ansible | TASK [Gathering Facts] ******************************************************************************************************************************
2020-05-24 17:40:02,737 p=21217 u=root n=ansible | ok: [node02]
2020-05-24 17:40:02,987 p=21217 u=root n=ansible | ok: [node03]
2020-05-24 17:40:03,046 p=21217 u=root n=ansible | ok: [node01]
2020-05-24 17:40:03,080 p=21217 u=root n=ansible | TASK [loading file] *********************************************************************************************************************************
2020-05-24 17:40:04,368 p=21217 u=root n=ansible | changed: [node02]
2020-05-24 17:40:04,518 p=21217 u=root n=ansible | changed: [node01]
2020-05-24 17:40:04,523 p=21217 u=root n=ansible | changed: [node03]
2020-05-24 17:40:04,559 p=21217 u=root n=ansible | TASK [Adding files] *********************************************************************************************************************************
2020-05-24 17:40:05,782 p=21217 u=root n=ansible | An exception occurred during task execution. To see the full traceback, use -vvv. The error was: NameError: name 'op' is not defined
2020-05-24 17:40:05,783 p=21217 u=root n=ansible | fatal: [node02]: FAILED! => {"changed": false, "module_stderr": "Shared connection to 192.168.56.2 closed.\r\n", "module_stdout": "Traceback (most recent call last):\r\n  File \"/home/vagrant/.ansible/tmp/ansible-tmp-1590331204.6705692-216047431893052/AnsiballZ_wordmatch.py\", line 102, in <module>\r\n    _ansiballz_main()\r\n  File \"/home/vagrant/.ansible/tmp/ansible-tmp-1590331204.6705692-216047431893052/AnsiballZ_wordmatch.py\", line 94, in _ansiballz_main\r\n    invoke_module(zipped_mod, temp_path, ANSIBALLZ_PARAMS)\r\n  File \"/home/vagrant/.ansible/tmp/ansible-tmp-1590331204.6705692-216047431893052/AnsiballZ_wordmatch.py\", line 40, in invoke_module\r\n    runpy.run_module(mod_name='ansible.modules.wordmatch', init_globals=None, run_name='__main__', alter_sys=True)\r\n  File \"/usr/lib64/python2.7/runpy.py\", line 176, in run_module\r\n    fname, loader, pkg_name)\r\n  File \"/usr/lib64/python2.7/runpy.py\", line 82, in _run_module_code\r\n    mod_name, mod_fname, mod_loader, pkg_name)\r\n  File \"/usr/lib64/python2.7/runpy.py\", line 72, in _run_code\r\n    exec code in run_globals\r\n  File \"/tmp/ansible_wordmatch_payload_2RfCiE/ansible_wordmatch_payload.zip/ansible/modules/wordmatch.py\", line 20, in <module>\r\nNameError: name 'op' is not defined\r\n", "msg": "MODULE FAILURE\nSee stdout/stderr for the exact error", "rc": 1}
2020-05-24 17:40:05,907 p=21217 u=root n=ansible | An exception occurred during task execution. To see the full traceback, use -vvv. The error was: NameError: name 'op' is not defined
2020-05-24 17:40:05,908 p=21217 u=root n=ansible | fatal: [node03]: FAILED! => {"changed": false, "module_stderr": "Shared connection to 192.168.56.2 closed.\r\n", "module_stdout": "Traceback (most recent call last):\r\n  File \"/home/vagrant/.ansible/tmp/ansible-tmp-1590331204.733203-60497156942030/AnsiballZ_wordmatch.py\", line 102, in <module>\r\n    _ansiballz_main()\r\n  File \"/home/vagrant/.ansible/tmp/ansible-tmp-1590331204.733203-60497156942030/AnsiballZ_wordmatch.py\", line 94, in _ansiballz_main\r\n    invoke_module(zipped_mod, temp_path, ANSIBALLZ_PARAMS)\r\n  File \"/home/vagrant/.ansible/tmp/ansible-tmp-1590331204.733203-60497156942030/AnsiballZ_wordmatch.py\", line 40, in invoke_module\r\n    runpy.run_module(mod_name='ansible.modules.wordmatch', init_globals=None, run_name='__main__', alter_sys=True)\r\n  File \"/usr/lib64/python2.7/runpy.py\", line 176, in run_module\r\n    fname, loader, pkg_name)\r\n  File \"/usr/lib64/python2.7/runpy.py\", line 82, in _run_module_code\r\n    mod_name, mod_fname, mod_loader, pkg_name)\r\n  File \"/usr/lib64/python2.7/runpy.py\", line 72, in _run_code\r\n    exec code in run_globals\r\n  File \"/tmp/ansible_wordmatch_payload_yPu_Og/ansible_wordmatch_payload.zip/ansible/modules/wordmatch.py\", line 20, in <module>\r\nNameError: name 'op' is not defined\r\n", "msg": "MODULE FAILURE\nSee stdout/stderr for the exact error", "rc": 1}
2020-05-24 17:40:05,929 p=21217 u=root n=ansible | An exception occurred during task execution. To see the full traceback, use -vvv. The error was: NameError: name 'op' is not defined
2020-05-24 17:40:05,929 p=21217 u=root n=ansible | fatal: [node01]: FAILED! => {"changed": false, "module_stderr": "Shared connection to 192.168.56.2 closed.\r\n", "module_stdout": "Traceback (most recent call last):\r\n  File \"/home/vagrant/.ansible/tmp/ansible-tmp-1590331204.5916126-231884722296637/AnsiballZ_wordmatch.py\", line 102, in <module>\r\n    _ansiballz_main()\r\n  File \"/home/vagrant/.ansible/tmp/ansible-tmp-1590331204.5916126-231884722296637/AnsiballZ_wordmatch.py\", line 94, in _ansiballz_main\r\n    invoke_module(zipped_mod, temp_path, ANSIBALLZ_PARAMS)\r\n  File \"/home/vagrant/.ansible/tmp/ansible-tmp-1590331204.5916126-231884722296637/AnsiballZ_wordmatch.py\", line 40, in invoke_module\r\n    runpy.run_module(mod_name='ansible.modules.wordmatch', init_globals=None, run_name='__main__', alter_sys=True)\r\n  File \"/usr/lib64/python2.7/runpy.py\", line 176, in run_module\r\n    fname, loader, pkg_name)\r\n  File \"/usr/lib64/python2.7/runpy.py\", line 82, in _run_module_code\r\n    mod_name, mod_fname, mod_loader, pkg_name)\r\n  File \"/usr/lib64/python2.7/runpy.py\", line 72, in _run_code\r\n    exec code in run_globals\r\n  File \"/tmp/ansible_wordmatch_payload_tL58vi/ansible_wordmatch_payload.zip/ansible/modules/wordmatch.py\", line 20, in <module>\r\nNameError: name 'op' is not defined\r\n", "msg": "MODULE FAILURE\nSee stdout/stderr for the exact error", "rc": 1}
2020-05-24 17:40:05,931 p=21217 u=root n=ansible | PLAY RECAP ******************************************************************************************************************************************
2020-05-24 17:40:05,931 p=21217 u=root n=ansible | node01                     : ok=2    changed=1    unreachable=0    failed=1    skipped=0    rescued=0    ignored=0   
2020-05-24 17:40:05,931 p=21217 u=root n=ansible | node02                     : ok=2    changed=1    unreachable=0    failed=1    skipped=0    rescued=0    ignored=0   
2020-05-24 17:40:05,932 p=21217 u=root n=ansible | node03                     : ok=2    changed=1    unreachable=0    failed=1    skipped=0    rescued=0    ignored=0   
2020-05-24 17:42:27,101 p=21503 u=root n=ansible | PLAY [dev] ******************************************************************************************************************************************
2020-05-24 17:42:27,121 p=21503 u=root n=ansible | TASK [Gathering Facts] ******************************************************************************************************************************
2020-05-24 17:42:30,699 p=21503 u=root n=ansible | ok: [node01]
2020-05-24 17:42:30,913 p=21503 u=root n=ansible | ok: [node03]
2020-05-24 17:42:30,962 p=21503 u=root n=ansible | ok: [node02]
2020-05-24 17:42:30,997 p=21503 u=root n=ansible | TASK [loading file] *********************************************************************************************************************************
2020-05-24 17:42:32,449 p=21503 u=root n=ansible | changed: [node02]
2020-05-24 17:42:32,464 p=21503 u=root n=ansible | changed: [node03]
2020-05-24 17:42:32,497 p=21503 u=root n=ansible | changed: [node01]
2020-05-24 17:42:32,528 p=21503 u=root n=ansible | TASK [Adding files] *********************************************************************************************************************************
2020-05-24 17:42:33,953 p=21503 u=root n=ansible | An exception occurred during task execution. To see the full traceback, use -vvv. The error was: NameError: name 'op' is not defined
2020-05-24 17:42:33,953 p=21503 u=root n=ansible | fatal: [node01]: FAILED! => {"changed": false, "module_stderr": "Shared connection to 192.168.56.2 closed.\r\n", "module_stdout": "Traceback (most recent call last):\r\n  File \"/home/vagrant/.ansible/tmp/ansible-tmp-1590331352.5643692-40907414375443/AnsiballZ_wordmatch.py\", line 102, in <module>\r\n    _ansiballz_main()\r\n  File \"/home/vagrant/.ansible/tmp/ansible-tmp-1590331352.5643692-40907414375443/AnsiballZ_wordmatch.py\", line 94, in _ansiballz_main\r\n    invoke_module(zipped_mod, temp_path, ANSIBALLZ_PARAMS)\r\n  File \"/home/vagrant/.ansible/tmp/ansible-tmp-1590331352.5643692-40907414375443/AnsiballZ_wordmatch.py\", line 40, in invoke_module\r\n    runpy.run_module(mod_name='ansible.modules.wordmatch', init_globals=None, run_name='__main__', alter_sys=True)\r\n  File \"/usr/lib64/python2.7/runpy.py\", line 176, in run_module\r\n    fname, loader, pkg_name)\r\n  File \"/usr/lib64/python2.7/runpy.py\", line 82, in _run_module_code\r\n    mod_name, mod_fname, mod_loader, pkg_name)\r\n  File \"/usr/lib64/python2.7/runpy.py\", line 72, in _run_code\r\n    exec code in run_globals\r\n  File \"/tmp/ansible_wordmatch_payload_4emM8f/ansible_wordmatch_payload.zip/ansible/modules/wordmatch.py\", line 20, in <module>\r\nNameError: name 'op' is not defined\r\n", "msg": "MODULE FAILURE\nSee stdout/stderr for the exact error", "rc": 1}
2020-05-24 17:42:34,017 p=21503 u=root n=ansible | An exception occurred during task execution. To see the full traceback, use -vvv. The error was: NameError: name 'op' is not defined
2020-05-24 17:42:34,018 p=21503 u=root n=ansible | fatal: [node03]: FAILED! => {"changed": false, "module_stderr": "Shared connection to 192.168.56.2 closed.\r\n", "module_stdout": "Traceback (most recent call last):\r\n  File \"/home/vagrant/.ansible/tmp/ansible-tmp-1590331352.727794-8540579054550/AnsiballZ_wordmatch.py\", line 102, in <module>\r\n    _ansiballz_main()\r\n  File \"/home/vagrant/.ansible/tmp/ansible-tmp-1590331352.727794-8540579054550/AnsiballZ_wordmatch.py\", line 94, in _ansiballz_main\r\n    invoke_module(zipped_mod, temp_path, ANSIBALLZ_PARAMS)\r\n  File \"/home/vagrant/.ansible/tmp/ansible-tmp-1590331352.727794-8540579054550/AnsiballZ_wordmatch.py\", line 40, in invoke_module\r\n    runpy.run_module(mod_name='ansible.modules.wordmatch', init_globals=None, run_name='__main__', alter_sys=True)\r\n  File \"/usr/lib64/python2.7/runpy.py\", line 176, in run_module\r\n    fname, loader, pkg_name)\r\n  File \"/usr/lib64/python2.7/runpy.py\", line 82, in _run_module_code\r\n    mod_name, mod_fname, mod_loader, pkg_name)\r\n  File \"/usr/lib64/python2.7/runpy.py\", line 72, in _run_code\r\n    exec code in run_globals\r\n  File \"/tmp/ansible_wordmatch_payload_8XrKRh/ansible_wordmatch_payload.zip/ansible/modules/wordmatch.py\", line 20, in <module>\r\nNameError: name 'op' is not defined\r\n", "msg": "MODULE FAILURE\nSee stdout/stderr for the exact error", "rc": 1}
2020-05-24 17:42:34,049 p=21503 u=root n=ansible | An exception occurred during task execution. To see the full traceback, use -vvv. The error was: NameError: name 'op' is not defined
2020-05-24 17:42:34,049 p=21503 u=root n=ansible | fatal: [node02]: FAILED! => {"changed": false, "module_stderr": "Shared connection to 192.168.56.2 closed.\r\n", "module_stdout": "Traceback (most recent call last):\r\n  File \"/home/vagrant/.ansible/tmp/ansible-tmp-1590331352.6387045-12926391414778/AnsiballZ_wordmatch.py\", line 102, in <module>\r\n    _ansiballz_main()\r\n  File \"/home/vagrant/.ansible/tmp/ansible-tmp-1590331352.6387045-12926391414778/AnsiballZ_wordmatch.py\", line 94, in _ansiballz_main\r\n    invoke_module(zipped_mod, temp_path, ANSIBALLZ_PARAMS)\r\n  File \"/home/vagrant/.ansible/tmp/ansible-tmp-1590331352.6387045-12926391414778/AnsiballZ_wordmatch.py\", line 40, in invoke_module\r\n    runpy.run_module(mod_name='ansible.modules.wordmatch', init_globals=None, run_name='__main__', alter_sys=True)\r\n  File \"/usr/lib64/python2.7/runpy.py\", line 176, in run_module\r\n    fname, loader, pkg_name)\r\n  File \"/usr/lib64/python2.7/runpy.py\", line 82, in _run_module_code\r\n    mod_name, mod_fname, mod_loader, pkg_name)\r\n  File \"/usr/lib64/python2.7/runpy.py\", line 72, in _run_code\r\n    exec code in run_globals\r\n  File \"/tmp/ansible_wordmatch_payload_hX7UTJ/ansible_wordmatch_payload.zip/ansible/modules/wordmatch.py\", line 20, in <module>\r\nNameError: name 'op' is not defined\r\n", "msg": "MODULE FAILURE\nSee stdout/stderr for the exact error", "rc": 1}
2020-05-24 17:42:34,051 p=21503 u=root n=ansible | PLAY RECAP ******************************************************************************************************************************************
2020-05-24 17:42:34,051 p=21503 u=root n=ansible | node01                     : ok=2    changed=1    unreachable=0    failed=1    skipped=0    rescued=0    ignored=0   
2020-05-24 17:42:34,051 p=21503 u=root n=ansible | node02                     : ok=2    changed=1    unreachable=0    failed=1    skipped=0    rescued=0    ignored=0   
2020-05-24 17:42:34,051 p=21503 u=root n=ansible | node03                     : ok=2    changed=1    unreachable=0    failed=1    skipped=0    rescued=0    ignored=0   
2020-05-24 18:17:05,487 p=23347 u=root n=ansible | PLAY [dev] ******************************************************************************************************************************************
2020-05-24 18:17:05,510 p=23347 u=root n=ansible | TASK [Gathering Facts] ******************************************************************************************************************************
2020-05-24 18:17:08,806 p=23347 u=root n=ansible | ok: [node01]
2020-05-24 18:17:08,892 p=23347 u=root n=ansible | ok: [node02]
2020-05-24 18:17:08,929 p=23347 u=root n=ansible | ok: [node03]
2020-05-24 18:17:08,964 p=23347 u=root n=ansible | TASK [loading file] *********************************************************************************************************************************
2020-05-24 18:17:10,252 p=23347 u=root n=ansible | changed: [node01]
2020-05-24 18:17:10,401 p=23347 u=root n=ansible | changed: [node02]
2020-05-24 18:17:10,408 p=23347 u=root n=ansible | changed: [node03]
2020-05-24 18:17:10,440 p=23347 u=root n=ansible | TASK [Adding files] *********************************************************************************************************************************
2020-05-24 18:17:11,627 p=23347 u=root n=ansible | An exception occurred during task execution. To see the full traceback, use -vvv. The error was: NameError: name 'op' is not defined
2020-05-24 18:17:11,628 p=23347 u=root n=ansible | fatal: [node01]: FAILED! => {"changed": false, "module_stderr": "Shared connection to 192.168.56.2 closed.\r\n", "module_stdout": "Traceback (most recent call last):\r\n  File \"/home/vagrant/.ansible/tmp/ansible-tmp-1590333430.475729-249055373588891/AnsiballZ_wordmatch.py\", line 102, in <module>\r\n    _ansiballz_main()\r\n  File \"/home/vagrant/.ansible/tmp/ansible-tmp-1590333430.475729-249055373588891/AnsiballZ_wordmatch.py\", line 94, in _ansiballz_main\r\n    invoke_module(zipped_mod, temp_path, ANSIBALLZ_PARAMS)\r\n  File \"/home/vagrant/.ansible/tmp/ansible-tmp-1590333430.475729-249055373588891/AnsiballZ_wordmatch.py\", line 40, in invoke_module\r\n    runpy.run_module(mod_name='ansible.modules.wordmatch', init_globals=None, run_name='__main__', alter_sys=True)\r\n  File \"/usr/lib64/python2.7/runpy.py\", line 176, in run_module\r\n    fname, loader, pkg_name)\r\n  File \"/usr/lib64/python2.7/runpy.py\", line 82, in _run_module_code\r\n    mod_name, mod_fname, mod_loader, pkg_name)\r\n  File \"/usr/lib64/python2.7/runpy.py\", line 72, in _run_code\r\n    exec code in run_globals\r\n  File \"/tmp/ansible_wordmatch_payload_bRHnwm/ansible_wordmatch_payload.zip/ansible/modules/wordmatch.py\", line 20, in <module>\r\nNameError: name 'op' is not defined\r\n", "msg": "MODULE FAILURE\nSee stdout/stderr for the exact error", "rc": 1}
2020-05-24 18:17:11,748 p=23347 u=root n=ansible | An exception occurred during task execution. To see the full traceback, use -vvv. The error was: NameError: name 'op' is not defined
2020-05-24 18:17:11,748 p=23347 u=root n=ansible | fatal: [node02]: FAILED! => {"changed": false, "module_stderr": "Shared connection to 192.168.56.2 closed.\r\n", "module_stdout": "Traceback (most recent call last):\r\n  File \"/home/vagrant/.ansible/tmp/ansible-tmp-1590333430.5384562-180644394261427/AnsiballZ_wordmatch.py\", line 102, in <module>\r\n    _ansiballz_main()\r\n  File \"/home/vagrant/.ansible/tmp/ansible-tmp-1590333430.5384562-180644394261427/AnsiballZ_wordmatch.py\", line 94, in _ansiballz_main\r\n    invoke_module(zipped_mod, temp_path, ANSIBALLZ_PARAMS)\r\n  File \"/home/vagrant/.ansible/tmp/ansible-tmp-1590333430.5384562-180644394261427/AnsiballZ_wordmatch.py\", line 40, in invoke_module\r\n    runpy.run_module(mod_name='ansible.modules.wordmatch', init_globals=None, run_name='__main__', alter_sys=True)\r\n  File \"/usr/lib64/python2.7/runpy.py\", line 176, in run_module\r\n    fname, loader, pkg_name)\r\n  File \"/usr/lib64/python2.7/runpy.py\", line 82, in _run_module_code\r\n    mod_name, mod_fname, mod_loader, pkg_name)\r\n  File \"/usr/lib64/python2.7/runpy.py\", line 72, in _run_code\r\n    exec code in run_globals\r\n  File \"/tmp/ansible_wordmatch_payload_hTVYNS/ansible_wordmatch_payload.zip/ansible/modules/wordmatch.py\", line 20, in <module>\r\nNameError: name 'op' is not defined\r\n", "msg": "MODULE FAILURE\nSee stdout/stderr for the exact error", "rc": 1}
2020-05-24 18:17:11,764 p=23347 u=root n=ansible | An exception occurred during task execution. To see the full traceback, use -vvv. The error was: NameError: name 'op' is not defined
2020-05-24 18:17:11,764 p=23347 u=root n=ansible | fatal: [node03]: FAILED! => {"changed": false, "module_stderr": "Shared connection to 192.168.56.2 closed.\r\n", "module_stdout": "Traceback (most recent call last):\r\n  File \"/home/vagrant/.ansible/tmp/ansible-tmp-1590333430.5982544-169242932465281/AnsiballZ_wordmatch.py\", line 102, in <module>\r\n    _ansiballz_main()\r\n  File \"/home/vagrant/.ansible/tmp/ansible-tmp-1590333430.5982544-169242932465281/AnsiballZ_wordmatch.py\", line 94, in _ansiballz_main\r\n    invoke_module(zipped_mod, temp_path, ANSIBALLZ_PARAMS)\r\n  File \"/home/vagrant/.ansible/tmp/ansible-tmp-1590333430.5982544-169242932465281/AnsiballZ_wordmatch.py\", line 40, in invoke_module\r\n    runpy.run_module(mod_name='ansible.modules.wordmatch', init_globals=None, run_name='__main__', alter_sys=True)\r\n  File \"/usr/lib64/python2.7/runpy.py\", line 176, in run_module\r\n    fname, loader, pkg_name)\r\n  File \"/usr/lib64/python2.7/runpy.py\", line 82, in _run_module_code\r\n    mod_name, mod_fname, mod_loader, pkg_name)\r\n  File \"/usr/lib64/python2.7/runpy.py\", line 72, in _run_code\r\n    exec code in run_globals\r\n  File \"/tmp/ansible_wordmatch_payload_yOV7Gj/ansible_wordmatch_payload.zip/ansible/modules/wordmatch.py\", line 20, in <module>\r\nNameError: name 'op' is not defined\r\n", "msg": "MODULE FAILURE\nSee stdout/stderr for the exact error", "rc": 1}
2020-05-24 18:17:11,766 p=23347 u=root n=ansible | PLAY RECAP ******************************************************************************************************************************************
2020-05-24 18:17:11,766 p=23347 u=root n=ansible | node01                     : ok=2    changed=1    unreachable=0    failed=1    skipped=0    rescued=0    ignored=0   
2020-05-24 18:17:11,766 p=23347 u=root n=ansible | node02                     : ok=2    changed=1    unreachable=0    failed=1    skipped=0    rescued=0    ignored=0   
2020-05-24 18:17:11,766 p=23347 u=root n=ansible | node03                     : ok=2    changed=1    unreachable=0    failed=1    skipped=0    rescued=0    ignored=0   
2020-05-24 18:17:29,657 p=23541 u=root n=ansible | PLAY [dev] ******************************************************************************************************************************************
2020-05-24 18:17:29,677 p=23541 u=root n=ansible | TASK [Gathering Facts] ******************************************************************************************************************************
2020-05-24 18:17:32,424 p=23541 u=root n=ansible | ok: [node02]
2020-05-24 18:17:32,584 p=23541 u=root n=ansible | ok: [node01]
2020-05-24 18:17:32,593 p=23541 u=root n=ansible | ok: [node03]
2020-05-24 18:17:32,631 p=23541 u=root n=ansible | TASK [loading file] *********************************************************************************************************************************
2020-05-24 18:17:33,881 p=23541 u=root n=ansible | changed: [node02]
2020-05-24 18:17:34,039 p=23541 u=root n=ansible | changed: [node01]
2020-05-24 18:17:34,044 p=23541 u=root n=ansible | changed: [node03]
2020-05-24 18:17:34,076 p=23541 u=root n=ansible | TASK [Adding files] *********************************************************************************************************************************
2020-05-24 18:17:35,283 p=23541 u=root n=ansible | fatal: [node02]: FAILED! => {"changed": false, "msg": "missing required arguments: op"}
2020-05-24 18:17:35,430 p=23541 u=root n=ansible | fatal: [node01]: FAILED! => {"changed": false, "msg": "missing required arguments: op"}
2020-05-24 18:17:35,434 p=23541 u=root n=ansible | fatal: [node03]: FAILED! => {"changed": false, "msg": "missing required arguments: op"}
2020-05-24 18:17:35,436 p=23541 u=root n=ansible | PLAY RECAP ******************************************************************************************************************************************
2020-05-24 18:17:35,436 p=23541 u=root n=ansible | node01                     : ok=2    changed=1    unreachable=0    failed=1    skipped=0    rescued=0    ignored=0   
2020-05-24 18:17:35,437 p=23541 u=root n=ansible | node02                     : ok=2    changed=1    unreachable=0    failed=1    skipped=0    rescued=0    ignored=0   
2020-05-24 18:17:35,437 p=23541 u=root n=ansible | node03                     : ok=2    changed=1    unreachable=0    failed=1    skipped=0    rescued=0    ignored=0   
2020-05-24 18:17:54,679 p=23726 u=root n=ansible | PLAY [dev] ******************************************************************************************************************************************
2020-05-24 18:17:54,699 p=23726 u=root n=ansible | TASK [Gathering Facts] ******************************************************************************************************************************
2020-05-24 18:17:57,258 p=23726 u=root n=ansible | ok: [node03]
2020-05-24 18:17:57,644 p=23726 u=root n=ansible | ok: [node01]
2020-05-24 18:17:57,656 p=23726 u=root n=ansible | ok: [node02]
2020-05-24 18:17:57,689 p=23726 u=root n=ansible | TASK [loading file] *********************************************************************************************************************************
2020-05-24 18:17:58,906 p=23726 u=root n=ansible | changed: [node02]
2020-05-24 18:17:59,068 p=23726 u=root n=ansible | changed: [node01]
2020-05-24 18:17:59,075 p=23726 u=root n=ansible | changed: [node03]
2020-05-24 18:17:59,106 p=23726 u=root n=ansible | TASK [Adding files] *********************************************************************************************************************************
2020-05-24 18:18:00,291 p=23726 u=root n=ansible | An exception occurred during task execution. To see the full traceback, use -vvv. The error was: NameError: name 'op' is not defined
2020-05-24 18:18:00,291 p=23726 u=root n=ansible | fatal: [node02]: FAILED! => {"changed": false, "module_stderr": "Shared connection to 192.168.56.2 closed.\r\n", "module_stdout": "Traceback (most recent call last):\r\n  File \"/home/vagrant/.ansible/tmp/ansible-tmp-1590333479.2114108-170486034712414/AnsiballZ_wordmatch.py\", line 102, in <module>\r\n    _ansiballz_main()\r\n  File \"/home/vagrant/.ansible/tmp/ansible-tmp-1590333479.2114108-170486034712414/AnsiballZ_wordmatch.py\", line 94, in _ansiballz_main\r\n    invoke_module(zipped_mod, temp_path, ANSIBALLZ_PARAMS)\r\n  File \"/home/vagrant/.ansible/tmp/ansible-tmp-1590333479.2114108-170486034712414/AnsiballZ_wordmatch.py\", line 40, in invoke_module\r\n    runpy.run_module(mod_name='ansible.modules.wordmatch', init_globals=None, run_name='__main__', alter_sys=True)\r\n  File \"/usr/lib64/python2.7/runpy.py\", line 176, in run_module\r\n    fname, loader, pkg_name)\r\n  File \"/usr/lib64/python2.7/runpy.py\", line 82, in _run_module_code\r\n    mod_name, mod_fname, mod_loader, pkg_name)\r\n  File \"/usr/lib64/python2.7/runpy.py\", line 72, in _run_code\r\n    exec code in run_globals\r\n  File \"/tmp/ansible_wordmatch_payload_GawM6U/ansible_wordmatch_payload.zip/ansible/modules/wordmatch.py\", line 20, in <module>\r\nNameError: name 'op' is not defined\r\n", "msg": "MODULE FAILURE\nSee stdout/stderr for the exact error", "rc": 1}
2020-05-24 18:18:00,441 p=23726 u=root n=ansible | An exception occurred during task execution. To see the full traceback, use -vvv. The error was: NameError: name 'op' is not defined
2020-05-24 18:18:00,441 p=23726 u=root n=ansible | fatal: [node01]: FAILED! => {"changed": false, "module_stderr": "Shared connection to 192.168.56.2 closed.\r\n", "module_stdout": "Traceback (most recent call last):\r\n  File \"/home/vagrant/.ansible/tmp/ansible-tmp-1590333479.1391087-127005431658533/AnsiballZ_wordmatch.py\", line 102, in <module>\r\n    _ansiballz_main()\r\n  File \"/home/vagrant/.ansible/tmp/ansible-tmp-1590333479.1391087-127005431658533/AnsiballZ_wordmatch.py\", line 94, in _ansiballz_main\r\n    invoke_module(zipped_mod, temp_path, ANSIBALLZ_PARAMS)\r\n  File \"/home/vagrant/.ansible/tmp/ansible-tmp-1590333479.1391087-127005431658533/AnsiballZ_wordmatch.py\", line 40, in invoke_module\r\n    runpy.run_module(mod_name='ansible.modules.wordmatch', init_globals=None, run_name='__main__', alter_sys=True)\r\n  File \"/usr/lib64/python2.7/runpy.py\", line 176, in run_module\r\n    fname, loader, pkg_name)\r\n  File \"/usr/lib64/python2.7/runpy.py\", line 82, in _run_module_code\r\n    mod_name, mod_fname, mod_loader, pkg_name)\r\n  File \"/usr/lib64/python2.7/runpy.py\", line 72, in _run_code\r\n    exec code in run_globals\r\n  File \"/tmp/ansible_wordmatch_payload_k6m7ev/ansible_wordmatch_payload.zip/ansible/modules/wordmatch.py\", line 20, in <module>\r\nNameError: name 'op' is not defined\r\n", "msg": "MODULE FAILURE\nSee stdout/stderr for the exact error", "rc": 1}
2020-05-24 18:18:00,459 p=23726 u=root n=ansible | An exception occurred during task execution. To see the full traceback, use -vvv. The error was: NameError: name 'op' is not defined
2020-05-24 18:18:00,459 p=23726 u=root n=ansible | fatal: [node03]: FAILED! => {"changed": false, "module_stderr": "Shared connection to 192.168.56.2 closed.\r\n", "module_stdout": "Traceback (most recent call last):\r\n  File \"/home/vagrant/.ansible/tmp/ansible-tmp-1590333479.284637-255149966691519/AnsiballZ_wordmatch.py\", line 102, in <module>\r\n    _ansiballz_main()\r\n  File \"/home/vagrant/.ansible/tmp/ansible-tmp-1590333479.284637-255149966691519/AnsiballZ_wordmatch.py\", line 94, in _ansiballz_main\r\n    invoke_module(zipped_mod, temp_path, ANSIBALLZ_PARAMS)\r\n  File \"/home/vagrant/.ansible/tmp/ansible-tmp-1590333479.284637-255149966691519/AnsiballZ_wordmatch.py\", line 40, in invoke_module\r\n    runpy.run_module(mod_name='ansible.modules.wordmatch', init_globals=None, run_name='__main__', alter_sys=True)\r\n  File \"/usr/lib64/python2.7/runpy.py\", line 176, in run_module\r\n    fname, loader, pkg_name)\r\n  File \"/usr/lib64/python2.7/runpy.py\", line 82, in _run_module_code\r\n    mod_name, mod_fname, mod_loader, pkg_name)\r\n  File \"/usr/lib64/python2.7/runpy.py\", line 72, in _run_code\r\n    exec code in run_globals\r\n  File \"/tmp/ansible_wordmatch_payload_h8rOlS/ansible_wordmatch_payload.zip/ansible/modules/wordmatch.py\", line 20, in <module>\r\nNameError: name 'op' is not defined\r\n", "msg": "MODULE FAILURE\nSee stdout/stderr for the exact error", "rc": 1}
2020-05-24 18:18:00,460 p=23726 u=root n=ansible | PLAY RECAP ******************************************************************************************************************************************
2020-05-24 18:18:00,461 p=23726 u=root n=ansible | node01                     : ok=2    changed=1    unreachable=0    failed=1    skipped=0    rescued=0    ignored=0   
2020-05-24 18:18:00,461 p=23726 u=root n=ansible | node02                     : ok=2    changed=1    unreachable=0    failed=1    skipped=0    rescued=0    ignored=0   
2020-05-24 18:18:00,461 p=23726 u=root n=ansible | node03                     : ok=2    changed=1    unreachable=0    failed=1    skipped=0    rescued=0    ignored=0   
2020-05-24 18:22:34,479 p=24131 u=root n=ansible | PLAY [dev] ******************************************************************************************************************************************
2020-05-24 18:22:34,499 p=24131 u=root n=ansible | TASK [Gathering Facts] ******************************************************************************************************************************
2020-05-24 18:22:37,606 p=24131 u=root n=ansible | ok: [node02]
2020-05-24 18:22:37,981 p=24131 u=root n=ansible | ok: [node01]
2020-05-24 18:22:37,990 p=24131 u=root n=ansible | ok: [node03]
2020-05-24 18:22:38,024 p=24131 u=root n=ansible | TASK [loading file] *********************************************************************************************************************************
2020-05-24 18:22:39,246 p=24131 u=root n=ansible | changed: [node02]
2020-05-24 18:22:39,400 p=24131 u=root n=ansible | changed: [node03]
2020-05-24 18:22:39,413 p=24131 u=root n=ansible | changed: [node01]
2020-05-24 18:22:39,449 p=24131 u=root n=ansible | TASK [Adding files] *********************************************************************************************************************************
2020-05-24 18:22:40,666 p=24131 u=root n=ansible | ok: [node01]
2020-05-24 18:22:40,804 p=24131 u=root n=ansible | ok: [node03]
2020-05-24 18:22:40,809 p=24131 u=root n=ansible | ok: [node02]
2020-05-24 18:22:40,812 p=24131 u=root n=ansible | PLAY RECAP ******************************************************************************************************************************************
2020-05-24 18:22:40,812 p=24131 u=root n=ansible | node01                     : ok=3    changed=1    unreachable=0    failed=0    skipped=0    rescued=0    ignored=0   
2020-05-24 18:22:40,812 p=24131 u=root n=ansible | node02                     : ok=3    changed=1    unreachable=0    failed=0    skipped=0    rescued=0    ignored=0   
2020-05-24 18:22:40,812 p=24131 u=root n=ansible | node03                     : ok=3    changed=1    unreachable=0    failed=0    skipped=0    rescued=0    ignored=0   
2020-05-24 18:25:15,436 p=24437 u=root n=ansible | PLAY [dev] ******************************************************************************************************************************************
2020-05-24 18:25:15,456 p=24437 u=root n=ansible | TASK [Gathering Facts] ******************************************************************************************************************************
2020-05-24 18:25:18,733 p=24437 u=root n=ansible | ok: [node02]
2020-05-24 18:25:18,913 p=24437 u=root n=ansible | ok: [node01]
2020-05-24 18:25:18,925 p=24437 u=root n=ansible | ok: [node03]
2020-05-24 18:25:18,958 p=24437 u=root n=ansible | TASK [loading file] *********************************************************************************************************************************
2020-05-24 18:25:20,284 p=24437 u=root n=ansible | changed: [node03]
2020-05-24 18:25:20,381 p=24437 u=root n=ansible | changed: [node02]
2020-05-24 18:25:20,400 p=24437 u=root n=ansible | changed: [node01]
2020-05-24 18:25:20,432 p=24437 u=root n=ansible | TASK [Adding files] *********************************************************************************************************************************
2020-05-24 18:25:21,660 p=24437 u=root n=ansible | ok: [node01]
2020-05-24 18:25:21,788 p=24437 u=root n=ansible | ok: [node03]
2020-05-24 18:25:21,793 p=24437 u=root n=ansible | ok: [node02]
2020-05-24 18:25:21,834 p=24437 u=root n=ansible | TASK [Sameer] ***************************************************************************************************************************************
2020-05-24 18:25:21,997 p=24437 u=root n=ansible | fatal: [node01]: FAILED! => {"msg": "The task includes an option with an undefined variable. The error was: 'dict object' has no attribute 'stdout'\n\nThe error appears to be in '/root/automate/docker/words.yml': line 17, column 7, but may\nbe elsewhere in the file depending on the exact syntax problem.\n\nThe offending line appears to be:\n\n\n    - name: Sameer\n      ^ here\n"}
2020-05-24 18:25:22,067 p=24437 u=root n=ansible | fatal: [node02]: FAILED! => {"msg": "The task includes an option with an undefined variable. The error was: 'dict object' has no attribute 'stdout'\n\nThe error appears to be in '/root/automate/docker/words.yml': line 17, column 7, but may\nbe elsewhere in the file depending on the exact syntax problem.\n\nThe offending line appears to be:\n\n\n    - name: Sameer\n      ^ here\n"}
2020-05-24 18:25:22,098 p=24437 u=root n=ansible | fatal: [node03]: FAILED! => {"msg": "The task includes an option with an undefined variable. The error was: 'dict object' has no attribute 'stdout'\n\nThe error appears to be in '/root/automate/docker/words.yml': line 17, column 7, but may\nbe elsewhere in the file depending on the exact syntax problem.\n\nThe offending line appears to be:\n\n\n    - name: Sameer\n      ^ here\n"}
2020-05-24 18:25:22,099 p=24437 u=root n=ansible | PLAY RECAP ******************************************************************************************************************************************
2020-05-24 18:25:22,100 p=24437 u=root n=ansible | node01                     : ok=3    changed=1    unreachable=0    failed=1    skipped=0    rescued=0    ignored=0   
2020-05-24 18:25:22,100 p=24437 u=root n=ansible | node02                     : ok=3    changed=1    unreachable=0    failed=1    skipped=0    rescued=0    ignored=0   
2020-05-24 18:25:22,100 p=24437 u=root n=ansible | node03                     : ok=3    changed=1    unreachable=0    failed=1    skipped=0    rescued=0    ignored=0   
2020-05-24 18:27:18,972 p=24709 u=root n=ansible | PLAY [dev] ******************************************************************************************************************************************
2020-05-24 18:27:18,992 p=24709 u=root n=ansible | TASK [Gathering Facts] ******************************************************************************************************************************
2020-05-24 18:27:22,206 p=24709 u=root n=ansible | ok: [node03]
2020-05-24 18:27:22,437 p=24709 u=root n=ansible | ok: [node02]
2020-05-24 18:27:22,450 p=24709 u=root n=ansible | ok: [node01]
2020-05-24 18:27:22,484 p=24709 u=root n=ansible | TASK [loading file] *********************************************************************************************************************************
2020-05-24 18:27:23,719 p=24709 u=root n=ansible | changed: [node03]
2020-05-24 18:27:23,883 p=24709 u=root n=ansible | changed: [node01]
2020-05-24 18:27:23,890 p=24709 u=root n=ansible | changed: [node02]
2020-05-24 18:27:23,925 p=24709 u=root n=ansible | TASK [Adding files] *********************************************************************************************************************************
2020-05-24 18:27:25,169 p=24709 u=root n=ansible | ok: [node02]
2020-05-24 18:27:25,288 p=24709 u=root n=ansible | ok: [node01]
2020-05-24 18:27:25,294 p=24709 u=root n=ansible | ok: [node03]
2020-05-24 18:27:25,326 p=24709 u=root n=ansible | TASK [Sameer] ***************************************************************************************************************************************
2020-05-24 18:27:25,534 p=24709 u=root n=ansible | fatal: [node01]: FAILED! => {"msg": "The task includes an option with an undefined variable. The error was: 'dict object' has no attribute 'stdout'\n\nThe error appears to be in '/root/automate/docker/words.yml': line 17, column 7, but may\nbe elsewhere in the file depending on the exact syntax problem.\n\nThe offending line appears to be:\n\n\n    - name: Sameer\n      ^ here\n"}
2020-05-24 18:27:25,597 p=24709 u=root n=ansible | fatal: [node02]: FAILED! => {"msg": "The task includes an option with an undefined variable. The error was: 'dict object' has no attribute 'stdout'\n\nThe error appears to be in '/root/automate/docker/words.yml': line 17, column 7, but may\nbe elsewhere in the file depending on the exact syntax problem.\n\nThe offending line appears to be:\n\n\n    - name: Sameer\n      ^ here\n"}
2020-05-24 18:27:25,634 p=24709 u=root n=ansible | fatal: [node03]: FAILED! => {"msg": "The task includes an option with an undefined variable. The error was: 'dict object' has no attribute 'stdout'\n\nThe error appears to be in '/root/automate/docker/words.yml': line 17, column 7, but may\nbe elsewhere in the file depending on the exact syntax problem.\n\nThe offending line appears to be:\n\n\n    - name: Sameer\n      ^ here\n"}
2020-05-24 18:27:25,636 p=24709 u=root n=ansible | PLAY RECAP ******************************************************************************************************************************************
2020-05-24 18:27:25,636 p=24709 u=root n=ansible | node01                     : ok=3    changed=1    unreachable=0    failed=1    skipped=0    rescued=0    ignored=0   
2020-05-24 18:27:25,636 p=24709 u=root n=ansible | node02                     : ok=3    changed=1    unreachable=0    failed=1    skipped=0    rescued=0    ignored=0   
2020-05-24 18:27:25,636 p=24709 u=root n=ansible | node03                     : ok=3    changed=1    unreachable=0    failed=1    skipped=0    rescued=0    ignored=0   
2020-05-24 18:29:48,094 p=25003 u=root n=ansible | PLAY [dev] ******************************************************************************************************************************************
2020-05-24 18:29:48,114 p=25003 u=root n=ansible | TASK [Gathering Facts] ******************************************************************************************************************************
2020-05-24 18:29:51,456 p=25003 u=root n=ansible | ok: [node01]
2020-05-24 18:29:51,695 p=25003 u=root n=ansible | ok: [node02]
2020-05-24 18:29:51,704 p=25003 u=root n=ansible | ok: [node03]
2020-05-24 18:29:51,745 p=25003 u=root n=ansible | TASK [loading file] *********************************************************************************************************************************
2020-05-24 18:29:53,139 p=25003 u=root n=ansible | changed: [node02]
2020-05-24 18:29:53,242 p=25003 u=root n=ansible | changed: [node03]
2020-05-24 18:29:53,251 p=25003 u=root n=ansible | changed: [node01]
2020-05-24 18:29:53,285 p=25003 u=root n=ansible | TASK [Adding files] *********************************************************************************************************************************
2020-05-24 18:29:54,600 p=25003 u=root n=ansible | ok: [node02]
2020-05-24 18:29:54,742 p=25003 u=root n=ansible | ok: [node01]
2020-05-24 18:29:54,748 p=25003 u=root n=ansible | ok: [node03]
2020-05-24 18:29:54,781 p=25003 u=root n=ansible | TASK [Sameer] ***************************************************************************************************************************************
2020-05-24 18:29:54,948 p=25003 u=root n=ansible | fatal: [node01]: FAILED! => {"msg": "The task includes an option with an undefined variable. The error was: 'dict object' has no attribute 'stdout'\n\nThe error appears to be in '/root/automate/docker/words.yml': line 17, column 7, but may\nbe elsewhere in the file depending on the exact syntax problem.\n\nThe offending line appears to be:\n\n\n    - name: Sameer\n      ^ here\n"}
2020-05-24 18:29:55,010 p=25003 u=root n=ansible | fatal: [node02]: FAILED! => {"msg": "The task includes an option with an undefined variable. The error was: 'dict object' has no attribute 'stdout'\n\nThe error appears to be in '/root/automate/docker/words.yml': line 17, column 7, but may\nbe elsewhere in the file depending on the exact syntax problem.\n\nThe offending line appears to be:\n\n\n    - name: Sameer\n      ^ here\n"}
2020-05-24 18:29:55,051 p=25003 u=root n=ansible | fatal: [node03]: FAILED! => {"msg": "The task includes an option with an undefined variable. The error was: 'dict object' has no attribute 'stdout'\n\nThe error appears to be in '/root/automate/docker/words.yml': line 17, column 7, but may\nbe elsewhere in the file depending on the exact syntax problem.\n\nThe offending line appears to be:\n\n\n    - name: Sameer\n      ^ here\n"}
2020-05-24 18:29:55,052 p=25003 u=root n=ansible | PLAY RECAP ******************************************************************************************************************************************
2020-05-24 18:29:55,053 p=25003 u=root n=ansible | node01                     : ok=3    changed=1    unreachable=0    failed=1    skipped=0    rescued=0    ignored=0   
2020-05-24 18:29:55,053 p=25003 u=root n=ansible | node02                     : ok=3    changed=1    unreachable=0    failed=1    skipped=0    rescued=0    ignored=0   
2020-05-24 18:29:55,053 p=25003 u=root n=ansible | node03                     : ok=3    changed=1    unreachable=0    failed=1    skipped=0    rescued=0    ignored=0   
2020-05-24 18:32:57,137 p=25327 u=root n=ansible | PLAY [dev] ******************************************************************************************************************************************
2020-05-24 18:32:57,158 p=25327 u=root n=ansible | TASK [Gathering Facts] ******************************************************************************************************************************
2020-05-24 18:33:00,343 p=25327 u=root n=ansible | ok: [node02]
2020-05-24 18:33:00,531 p=25327 u=root n=ansible | ok: [node03]
2020-05-24 18:33:00,545 p=25327 u=root n=ansible | ok: [node01]
2020-05-24 18:33:00,578 p=25327 u=root n=ansible | TASK [loading file] *********************************************************************************************************************************
2020-05-24 18:33:01,787 p=25327 u=root n=ansible | changed: [node02]
2020-05-24 18:33:01,985 p=25327 u=root n=ansible | changed: [node03]
2020-05-24 18:33:01,990 p=25327 u=root n=ansible | changed: [node01]
2020-05-24 18:33:02,021 p=25327 u=root n=ansible | TASK [Adding files] *********************************************************************************************************************************
2020-05-24 18:33:03,345 p=25327 u=root n=ansible | ok: [node01]
2020-05-24 18:33:03,421 p=25327 u=root n=ansible | ok: [node02]
2020-05-24 18:33:03,425 p=25327 u=root n=ansible | ok: [node03]
2020-05-24 18:33:03,460 p=25327 u=root n=ansible | TASK [Sameer] ***************************************************************************************************************************************
2020-05-24 18:33:03,640 p=25327 u=root n=ansible | fatal: [node01]: FAILED! => {"msg": "The task includes an option with an undefined variable. The error was: 'dict object' has no attribute 'stdout'\n\nThe error appears to be in '/root/automate/docker/words.yml': line 17, column 7, but may\nbe elsewhere in the file depending on the exact syntax problem.\n\nThe offending line appears to be:\n\n\n    - name: Sameer\n      ^ here\n"}
2020-05-24 18:33:03,701 p=25327 u=root n=ansible | fatal: [node02]: FAILED! => {"msg": "The task includes an option with an undefined variable. The error was: 'dict object' has no attribute 'stdout'\n\nThe error appears to be in '/root/automate/docker/words.yml': line 17, column 7, but may\nbe elsewhere in the file depending on the exact syntax problem.\n\nThe offending line appears to be:\n\n\n    - name: Sameer\n      ^ here\n"}
2020-05-24 18:33:03,738 p=25327 u=root n=ansible | fatal: [node03]: FAILED! => {"msg": "The task includes an option with an undefined variable. The error was: 'dict object' has no attribute 'stdout'\n\nThe error appears to be in '/root/automate/docker/words.yml': line 17, column 7, but may\nbe elsewhere in the file depending on the exact syntax problem.\n\nThe offending line appears to be:\n\n\n    - name: Sameer\n      ^ here\n"}
2020-05-24 18:33:03,740 p=25327 u=root n=ansible | PLAY RECAP ******************************************************************************************************************************************
2020-05-24 18:33:03,740 p=25327 u=root n=ansible | node01                     : ok=3    changed=1    unreachable=0    failed=1    skipped=0    rescued=0    ignored=0   
2020-05-24 18:33:03,740 p=25327 u=root n=ansible | node02                     : ok=3    changed=1    unreachable=0    failed=1    skipped=0    rescued=0    ignored=0   
2020-05-24 18:33:03,740 p=25327 u=root n=ansible | node03                     : ok=3    changed=1    unreachable=0    failed=1    skipped=0    rescued=0    ignored=0   
2020-05-24 18:33:59,649 p=25551 u=root n=ansible | PLAY [dev] ******************************************************************************************************************************************
2020-05-24 18:33:59,669 p=25551 u=root n=ansible | TASK [Gathering Facts] ******************************************************************************************************************************
2020-05-24 18:34:02,543 p=25551 u=root n=ansible | ok: [node03]
2020-05-24 18:34:02,700 p=25551 u=root n=ansible | ok: [node01]
2020-05-24 18:34:02,763 p=25551 u=root n=ansible | ok: [node02]
2020-05-24 18:34:02,798 p=25551 u=root n=ansible | TASK [loading file] *********************************************************************************************************************************
2020-05-24 18:34:04,212 p=25551 u=root n=ansible | changed: [node02]
2020-05-24 18:34:04,363 p=25551 u=root n=ansible | changed: [node01]
2020-05-24 18:34:04,368 p=25551 u=root n=ansible | changed: [node03]
2020-05-24 18:34:04,402 p=25551 u=root n=ansible | TASK [Adding files] *********************************************************************************************************************************
2020-05-24 18:34:06,003 p=25551 u=root n=ansible | ok: [node02]
2020-05-24 18:34:06,221 p=25551 u=root n=ansible | ok: [node01]
2020-05-24 18:34:06,229 p=25551 u=root n=ansible | ok: [node03]
2020-05-24 18:34:06,261 p=25551 u=root n=ansible | TASK [Sameer] ***************************************************************************************************************************************
2020-05-24 18:34:06,442 p=25551 u=root n=ansible | fatal: [node01]: FAILED! => {"msg": "The task includes an option with an undefined variable. The error was: 'dict object' has no attribute 'stdout'\n\nThe error appears to be in '/root/automate/docker/words.yml': line 17, column 7, but may\nbe elsewhere in the file depending on the exact syntax problem.\n\nThe offending line appears to be:\n\n\n    - name: Sameer\n      ^ here\n"}
2020-05-24 18:34:06,494 p=25551 u=root n=ansible | fatal: [node02]: FAILED! => {"msg": "The task includes an option with an undefined variable. The error was: 'dict object' has no attribute 'stdout'\n\nThe error appears to be in '/root/automate/docker/words.yml': line 17, column 7, but may\nbe elsewhere in the file depending on the exact syntax problem.\n\nThe offending line appears to be:\n\n\n    - name: Sameer\n      ^ here\n"}
2020-05-24 18:34:06,540 p=25551 u=root n=ansible | fatal: [node03]: FAILED! => {"msg": "The task includes an option with an undefined variable. The error was: 'dict object' has no attribute 'stdout'\n\nThe error appears to be in '/root/automate/docker/words.yml': line 17, column 7, but may\nbe elsewhere in the file depending on the exact syntax problem.\n\nThe offending line appears to be:\n\n\n    - name: Sameer\n      ^ here\n"}
2020-05-24 18:34:06,542 p=25551 u=root n=ansible | PLAY RECAP ******************************************************************************************************************************************
2020-05-24 18:34:06,542 p=25551 u=root n=ansible | node01                     : ok=3    changed=1    unreachable=0    failed=1    skipped=0    rescued=0    ignored=0   
2020-05-24 18:34:06,542 p=25551 u=root n=ansible | node02                     : ok=3    changed=1    unreachable=0    failed=1    skipped=0    rescued=0    ignored=0   
2020-05-24 18:34:06,542 p=25551 u=root n=ansible | node03                     : ok=3    changed=1    unreachable=0    failed=1    skipped=0    rescued=0    ignored=0   
2020-05-24 18:36:44,305 p=25853 u=root n=ansible | PLAY [dev] ******************************************************************************************************************************************
2020-05-24 18:36:44,324 p=25853 u=root n=ansible | TASK [Gathering Facts] ******************************************************************************************************************************
2020-05-24 18:36:47,484 p=25853 u=root n=ansible | ok: [node03]
2020-05-24 18:36:47,648 p=25853 u=root n=ansible | ok: [node02]
2020-05-24 18:36:47,664 p=25853 u=root n=ansible | ok: [node01]
2020-05-24 18:36:47,698 p=25853 u=root n=ansible | TASK [loading file] *********************************************************************************************************************************
2020-05-24 18:36:48,963 p=25853 u=root n=ansible | changed: [node02]
2020-05-24 18:36:49,079 p=25853 u=root n=ansible | changed: [node03]
2020-05-24 18:36:49,084 p=25853 u=root n=ansible | changed: [node01]
2020-05-24 18:36:49,116 p=25853 u=root n=ansible | TASK [Adding files] *********************************************************************************************************************************
2020-05-24 18:36:50,525 p=25853 u=root n=ansible | ok: [node02]
2020-05-24 18:36:50,626 p=25853 u=root n=ansible | ok: [node01]
2020-05-24 18:36:50,632 p=25853 u=root n=ansible | ok: [node03]
2020-05-24 18:36:50,665 p=25853 u=root n=ansible | TASK [Sameer] ***************************************************************************************************************************************
2020-05-24 18:36:50,843 p=25853 u=root n=ansible | fatal: [node01]: FAILED! => {"msg": "The task includes an option with an undefined variable. The error was: 'dict object' has no attribute 'stdout'\n\nThe error appears to be in '/root/automate/docker/words.yml': line 16, column 7, but may\nbe elsewhere in the file depending on the exact syntax problem.\n\nThe offending line appears to be:\n\n\n    - name: Sameer\n      ^ here\n"}
2020-05-24 18:36:50,894 p=25853 u=root n=ansible | fatal: [node02]: FAILED! => {"msg": "The task includes an option with an undefined variable. The error was: 'dict object' has no attribute 'stdout'\n\nThe error appears to be in '/root/automate/docker/words.yml': line 16, column 7, but may\nbe elsewhere in the file depending on the exact syntax problem.\n\nThe offending line appears to be:\n\n\n    - name: Sameer\n      ^ here\n"}
2020-05-24 18:36:50,931 p=25853 u=root n=ansible | fatal: [node03]: FAILED! => {"msg": "The task includes an option with an undefined variable. The error was: 'dict object' has no attribute 'stdout'\n\nThe error appears to be in '/root/automate/docker/words.yml': line 16, column 7, but may\nbe elsewhere in the file depending on the exact syntax problem.\n\nThe offending line appears to be:\n\n\n    - name: Sameer\n      ^ here\n"}
2020-05-24 18:36:50,932 p=25853 u=root n=ansible | PLAY RECAP ******************************************************************************************************************************************
2020-05-24 18:36:50,932 p=25853 u=root n=ansible | node01                     : ok=3    changed=1    unreachable=0    failed=1    skipped=0    rescued=0    ignored=0   
2020-05-24 18:36:50,933 p=25853 u=root n=ansible | node02                     : ok=3    changed=1    unreachable=0    failed=1    skipped=0    rescued=0    ignored=0   
2020-05-24 18:36:50,933 p=25853 u=root n=ansible | node03                     : ok=3    changed=1    unreachable=0    failed=1    skipped=0    rescued=0    ignored=0   
2020-05-24 19:13:44,147 p=27822 u=root n=ansible | PLAY [dev] ******************************************************************************************************************************************
2020-05-24 19:13:44,169 p=27822 u=root n=ansible | TASK [Gathering Facts] ******************************************************************************************************************************
2020-05-24 19:13:47,483 p=27822 u=root n=ansible | ok: [node03]
2020-05-24 19:13:47,673 p=27822 u=root n=ansible | ok: [node02]
2020-05-24 19:13:47,681 p=27822 u=root n=ansible | ok: [node01]
2020-05-24 19:13:47,716 p=27822 u=root n=ansible | TASK [loading file] *********************************************************************************************************************************
2020-05-24 19:13:48,980 p=27822 u=root n=ansible | changed: [node02]
2020-05-24 19:13:49,191 p=27822 u=root n=ansible | changed: [node03]
2020-05-24 19:13:49,201 p=27822 u=root n=ansible | changed: [node01]
2020-05-24 19:13:49,234 p=27822 u=root n=ansible | TASK [Adding files] *********************************************************************************************************************************
2020-05-24 19:13:50,730 p=27822 u=root n=ansible | ok: [node02]
2020-05-24 19:13:50,770 p=27822 u=root n=ansible | ok: [node03]
2020-05-24 19:13:50,793 p=27822 u=root n=ansible | ok: [node01]
2020-05-24 19:13:50,827 p=27822 u=root n=ansible | TASK [Sameer] ***************************************************************************************************************************************
2020-05-24 19:13:51,004 p=27822 u=root n=ansible | fatal: [node01]: FAILED! => {"msg": "The task includes an option with an undefined variable. The error was: 'dict object' has no attribute 'stdout'\n\nThe error appears to be in '/root/automate/docker/words.yml': line 17, column 7, but may\nbe elsewhere in the file depending on the exact syntax problem.\n\nThe offending line appears to be:\n\n\n    - name: Sameer\n      ^ here\n"}
2020-05-24 19:13:51,059 p=27822 u=root n=ansible | fatal: [node02]: FAILED! => {"msg": "The task includes an option with an undefined variable. The error was: 'dict object' has no attribute 'stdout'\n\nThe error appears to be in '/root/automate/docker/words.yml': line 17, column 7, but may\nbe elsewhere in the file depending on the exact syntax problem.\n\nThe offending line appears to be:\n\n\n    - name: Sameer\n      ^ here\n"}
2020-05-24 19:13:51,106 p=27822 u=root n=ansible | fatal: [node03]: FAILED! => {"msg": "The task includes an option with an undefined variable. The error was: 'dict object' has no attribute 'stdout'\n\nThe error appears to be in '/root/automate/docker/words.yml': line 17, column 7, but may\nbe elsewhere in the file depending on the exact syntax problem.\n\nThe offending line appears to be:\n\n\n    - name: Sameer\n      ^ here\n"}
2020-05-24 19:13:51,108 p=27822 u=root n=ansible | PLAY RECAP ******************************************************************************************************************************************
2020-05-24 19:13:51,108 p=27822 u=root n=ansible | node01                     : ok=3    changed=1    unreachable=0    failed=1    skipped=0    rescued=0    ignored=0   
2020-05-24 19:13:51,108 p=27822 u=root n=ansible | node02                     : ok=3    changed=1    unreachable=0    failed=1    skipped=0    rescued=0    ignored=0   
2020-05-24 19:13:51,108 p=27822 u=root n=ansible | node03                     : ok=3    changed=1    unreachable=0    failed=1    skipped=0    rescued=0    ignored=0   
2020-05-24 19:15:27,840 p=28078 u=root n=ansible | PLAY [dev] ******************************************************************************************************************************************
2020-05-24 19:15:27,864 p=28078 u=root n=ansible | TASK [Gathering Facts] ******************************************************************************************************************************
2020-05-24 19:15:31,338 p=28078 u=root n=ansible | ok: [node03]
2020-05-24 19:15:31,362 p=28078 u=root n=ansible | ok: [node02]
2020-05-24 19:15:31,404 p=28078 u=root n=ansible | ok: [node01]
2020-05-24 19:15:31,441 p=28078 u=root n=ansible | TASK [loading file] *********************************************************************************************************************************
2020-05-24 19:15:32,758 p=28078 u=root n=ansible | changed: [node02]
2020-05-24 19:15:32,910 p=28078 u=root n=ansible | changed: [node01]
2020-05-24 19:15:32,915 p=28078 u=root n=ansible | changed: [node03]
2020-05-24 19:15:32,947 p=28078 u=root n=ansible | TASK [Adding files] *********************************************************************************************************************************
2020-05-24 19:15:34,390 p=28078 u=root n=ansible | ok: [node03]
2020-05-24 19:15:34,521 p=28078 u=root n=ansible | ok: [node01]
2020-05-24 19:15:34,528 p=28078 u=root n=ansible | ok: [node02]
2020-05-24 19:15:34,562 p=28078 u=root n=ansible | TASK [Sameer] ***************************************************************************************************************************************
2020-05-24 19:15:34,758 p=28078 u=root n=ansible | ok: [node01] => {
    "msg": {
        "changed": false,
        "failed": false,
        "msg": "Need reboot"
    }
}
2020-05-24 19:15:34,809 p=28078 u=root n=ansible | ok: [node02] => {
    "msg": {
        "changed": false,
        "failed": false,
        "msg": "Need reboot"
    }
}
2020-05-24 19:15:34,853 p=28078 u=root n=ansible | ok: [node03] => {
    "msg": {
        "changed": false,
        "failed": false,
        "msg": "Need reboot"
    }
}
2020-05-24 19:15:34,857 p=28078 u=root n=ansible | PLAY RECAP ******************************************************************************************************************************************
2020-05-24 19:15:34,857 p=28078 u=root n=ansible | node01                     : ok=4    changed=1    unreachable=0    failed=0    skipped=0    rescued=0    ignored=0   
2020-05-24 19:15:34,857 p=28078 u=root n=ansible | node02                     : ok=4    changed=1    unreachable=0    failed=0    skipped=0    rescued=0    ignored=0   
2020-05-24 19:15:34,858 p=28078 u=root n=ansible | node03                     : ok=4    changed=1    unreachable=0    failed=0    skipped=0    rescued=0    ignored=0   
2020-05-24 19:16:15,148 p=28321 u=root n=ansible | PLAY [dev] ******************************************************************************************************************************************
2020-05-24 19:16:15,170 p=28321 u=root n=ansible | TASK [Gathering Facts] ******************************************************************************************************************************
2020-05-24 19:16:18,017 p=28321 u=root n=ansible | ok: [node02]
2020-05-24 19:16:18,110 p=28321 u=root n=ansible | ok: [node03]
2020-05-24 19:16:18,127 p=28321 u=root n=ansible | ok: [node01]
2020-05-24 19:16:18,161 p=28321 u=root n=ansible | TASK [loading file] *********************************************************************************************************************************
2020-05-24 19:16:19,478 p=28321 u=root n=ansible | changed: [node01]
2020-05-24 19:16:19,651 p=28321 u=root n=ansible | changed: [node02]
2020-05-24 19:16:19,656 p=28321 u=root n=ansible | changed: [node03]
2020-05-24 19:16:19,689 p=28321 u=root n=ansible | TASK [Adding files] *********************************************************************************************************************************
2020-05-24 19:16:21,149 p=28321 u=root n=ansible | ok: [node01]
2020-05-24 19:16:21,212 p=28321 u=root n=ansible | ok: [node03]
2020-05-24 19:16:21,240 p=28321 u=root n=ansible | ok: [node02]
2020-05-24 19:16:21,280 p=28321 u=root n=ansible | TASK [Sameer] ***************************************************************************************************************************************
2020-05-24 19:16:21,478 p=28321 u=root n=ansible | ok: [node01] => {
    "msg": {
        "changed": false,
        "failed": false,
        "msg": "Need reboot"
    }
}
2020-05-24 19:16:21,565 p=28321 u=root n=ansible | ok: [node02] => {
    "msg": {
        "changed": false,
        "failed": false,
        "msg": "Need reboot"
    }
}
2020-05-24 19:16:21,583 p=28321 u=root n=ansible | ok: [node03] => {
    "msg": {
        "changed": false,
        "failed": false,
        "msg": "Need reboot"
    }
}
2020-05-24 19:16:21,587 p=28321 u=root n=ansible | PLAY RECAP ******************************************************************************************************************************************
2020-05-24 19:16:21,587 p=28321 u=root n=ansible | node01                     : ok=4    changed=1    unreachable=0    failed=0    skipped=0    rescued=0    ignored=0   
2020-05-24 19:16:21,587 p=28321 u=root n=ansible | node02                     : ok=4    changed=1    unreachable=0    failed=0    skipped=0    rescued=0    ignored=0   
2020-05-24 19:16:21,588 p=28321 u=root n=ansible | node03                     : ok=4    changed=1    unreachable=0    failed=0    skipped=0    rescued=0    ignored=0   
